<?xml version="1.0" ?>
<robot name="robot" xmlns:xacro="http://www.ros.org/wiki/xacro">
  <!-- Materials -->
  <material name="white"><color rgba="1 1 1 1"/></material>
  <material name="orange"><color rgba="0.3 0 0.3 1"/></material>
  <material name="blue"><color rgba="0.2 0.2 1 1"/></material>
  <material name="black"><color rgba="0 0 0 1"/></material>
  <material name="red"><color rgba="1 0 0 1"/></material>
  <material name="gray"><color rgba="0.3 0.3 0.3 1"/></material>

  <!-- Base Link -->
  <link name="base_link"/>

  <link name="base_footprint"/>
  <joint name="base_footprint_joint" type="fixed">
    <parent link="base_link"/>
    <child link="base_footprint"/>
    <origin rpy="0 0 0" xyz="0 0 -0.138"/>
  </joint>

  <!-- Chassis -->
  <joint name="chassis_joint" type="fixed">
    <parent link="base_link"/>
    <child link="chassis"/>
    <origin xyz="-0.4 0 -0.05"/>
  </joint>

  <link name="chassis">
    <inertial>
      <origin rpy="0 0 0" xyz="0.25 0 0.1"/>
      <mass value="1.0"/>
      <inertia ixx="0.08666666666666667" ixy="0.0" ixz="0.0" iyy="0.02416666666666667" iyz="0.0" izz="0.10416666666666666"/>
    </inertial>
    <visual>
      <origin xyz="0.25 0 0.1"/>
      <geometry>
        <box size="0.5 1 0.2"/>
      </geometry>
      <material name="orange"/>
    </visual>
    <collision>
      <origin xyz="0.25 0 0.1"/>
      <geometry>
        <box size="0.5 1 0.2"/>
      </geometry>
    </collision>
  </link>
  <gazebo reference="chassis">
    <material>Gazebo/Orange</material>
  </gazebo>

  <!-- Left Wheel -->
  <joint name="left_wheel_joint" type="continuous">
    <parent link="base_link"/>
    <child link="left_wheel"/>
    <origin rpy="-1.5707963267948966 0 3.141592653589793" xyz="0 0.5 0.075"/>
    <axis xyz="0 0 1"/>
  </joint>

  <link name="left_wheel">
    <visual>
      <geometry>
        <cylinder length="0.026" radius="0.25"/>
      </geometry>
      <material name="blue"/>
    </visual>
    <collision>
      <geometry>
        <cylinder length="0.026" radius="0.25"/>
      </geometry>
    </collision>
    <inertial>
      <origin rpy="0 0 0" xyz="0 0 0"/>
      <mass value="0.05"/>
      <inertia ixx="0.0003" ixy="0.0" ixz="0.0" iyy="0.0003" iyz="0.0" izz="0.0005"/>
    </inertial>
  </link>
  <gazebo reference="left_wheel">
    <material>Gazebo/Blue</material>
  </gazebo>

  <!-- Right Wheel -->
  <joint name="right_wheel_joint" type="continuous">
    <parent link="base_link"/>
    <child link="right_wheel"/>
    <origin rpy="1.5707963267948966 0 3.141592653589793" xyz="0 -0.5 0.075"/>
    <axis xyz="0 0 -1"/>
  </joint>

  <link name="right_wheel">
    <visual>
      <geometry>
        <cylinder length="0.026" radius="0.25"/>
      </geometry>
      <material name="blue"/>
    </visual>
    <collision>
      <geometry>
        <cylinder length="0.026" radius="0.25"/>
      </geometry>
    </collision>
    <inertial>
      <origin rpy="0 0 0" xyz="0 0 0"/>
      <mass value="0.05"/>
      <inertia ixx="0.0003" ixy="0.0" ixz="0.0" iyy="0.0003" iyz="0.0" izz="0.0005"/>
    </inertial>
  </link>
  <gazebo reference="right_wheel">
    <material>Gazebo/Blue</material>
  </gazebo>

  <!-- Caster Wheel -->
  <joint name="caster_wheel_joint" type="fixed">
    <parent link="chassis"/>
    <child link="caster_wheel"/>
    <origin xyz="0.075 0 0.0"/>
  </joint>
  <link name="caster_wheel">
    <visual>
      <geometry>
        <sphere radius="0.05"/>
      </geometry>
      <material name="black"/>
    </visual>
    <collision>
      <geometry>
        <sphere radius="0.05"/>
      </geometry>
    </collision>
    <inertial>
      <origin rpy="0 0 0" xyz="0 0 0"/>
      <mass value="0.01"/>
      <inertia ixx="1e-5" ixy="0.0" ixz="0.0" iyy="1e-5" iyz="0.0" izz="1e-5"/>
    </inertial>
  </link>
  <gazebo reference="caster_wheel">
    <material>Gazebo/Black</material>
    <mu1 value="0.001"/>
    <mu2 value="0.001"/>
  </gazebo>

  <!-- Tail -->
  <joint name="tail" type="fixed">
    <parent link="chassis"/>
    <child link="tail_link"/>
    <origin rpy="0 0 0" xyz="0.5 0 0.22"/>
  </joint>
  <link name="tail_link">
    <visual>
      <geometry>
        <box size="0.25 0.05 0.05"/>
      </geometry>
      <material name="white"/>
    </visual>
    <collision>
      <geometry>
        <box size="0.25 0.05 0.05"/>
      </geometry>
    </collision>
    <inertial>
      <origin rpy="0 0 0" xyz="0.5 0 0.22"/>
      <mass value="0.001"/>
      <inertia ixx="4.17e-7" ixy="0.0" ixz="0.0" iyy="6.77e-5" iyz="0.0" izz="6.77e-5"/>
    </inertial>
  </link>
  <gazebo reference="tail_link">
    <material>Gazebo/White</material>
    <mu1 value="0.001"/>
    <mu2 value="0.001"/>
  </gazebo>

  <!-- Antenna -->
  <joint name="antenna_joint" type="fixed">
    <parent link="chassis"/>
    <child link="antenna"/>
    <origin xyz="0.4 -0.2 0.3" rpy="0 0 0"/>
  </joint>
  <link name="antenna">
    <visual>
      <geometry>
        <cylinder radius="0.02" length="0.3"/>
      </geometry>
      <material name="black"/>
    </visual>
    <collision>
      <geometry>
        <cylinder radius="0.02" length="0.3"/>
      </geometry>
    </collision>
    <inertial>
      <mass value="0.05"/>
      <origin xyz="0 0 0.15"/>
      <inertia ixx="0.0001" ixy="0" ixz="0" iyy="0.0001" iyz="0" izz="0.0001"/>
    </inertial>
  </link>
  <!-- Antenna2 -->
  <joint name="antenna2_joint" type="fixed">
    <parent link="chassis"/>
    <child link="antenna2"/>
    <origin xyz="0.4 0.2 0.3" rpy="0 0 0"/>
  </joint>
  <link name="antenna2">
    <visual>
      <geometry>
        <cylinder radius="0.02" length="0.3"/>
      </geometry>
      <material name="black"/>
    </visual>
    <collision>
      <geometry>
        <cylinder radius="0.02" length="0.3"/>
      </geometry>
    </collision>
    <inertial>
      <mass value="0.05"/>
      <origin xyz="0 0 0.15"/>
      <inertia ixx="0.0001" ixy="0" ixz="0" iyy="0.0001" iyz="0" izz="0.0001"/>
    </inertial>
  </link>

    <!-- Lidar -->
  <joint name="laser_joint" type="fixed">
    <parent link="base_link"/>
    <child link="laser_frame"/>
    <origin xyz="0.1 0 0.212" rpy="0 0 0"/>
  </joint>

  <link name="laser_frame">
    <visual>
      <geometry>
        <cylinder radius="0.05" length="0.04"/>
      </geometry>
      <material name="black"/>
    </visual>
    <visual>
      <origin xyz="0 0 -0.05"/>
      <geometry>
        <cylinder radius="0.01" length="0.1"/>
      </geometry>
      <material name="black"/>
    </visual>
    <collision>
      <geometry>
        <cylinder radius="0.05" length="0.04"/>
      </geometry>
    </collision>
    <inertial>
      <origin xyz="0 0 0" rpy="0 0 0"/>
      <mass value="0.1" />
      <inertia ixx="${(1/12) * 0.1 * (3*0.05*0.05 + 0.04*0.04)}" ixy="0.0" ixz="0.0"
               iyy="${(1/12) * 0.1 * (3*0.05*0.05 + 0.04*0.04)}" iyz="0.0"
               izz="${(1/2) * 0.1 * (0.05*0.05)}" />
    </inertial>
  </link>

  <gazebo reference="laser_frame">
    <material>Gazebo/Black</material>
    <sensor name='laser_sensor_frame' type='gpu_lidar'>
        <gz_frame_id>laser_frame</gz_frame_id>
        <pose>0 0 0 0 0 0</pose>
        <visualize>true</visualize>
        <always_on>true</always_on>
        <update_rate>20</update_rate>
        <ray>
            <scan>
                <horizontal>
                    <samples>360</samples>
                    <min_angle>-3.14</min_angle>
                    <max_angle>3.14</max_angle>
                </horizontal>
            </scan>
            <range>
                <min>0.3</min>
                <max>12</max>
            </range>
            <noise>
                <type>gaussian</type>
                <mean>0.0</mean>
                <stddev>0.007</stddev>
            </noise>
        </ray>
    </sensor>
  </gazebo>


  <!-- Plugins -->
  <gazebo>

    <plugin
    filename="gz-sim-joint-state-publisher-system"
    name="gz::sim::systems::JointStatePublisher">
    </plugin>

    <plugin filename="gz-sim-diff-drive-system" name="gz::sim::systems::DiffDrive">
      <left_joint>left_wheel_joint</left_joint>
      <right_joint>right_wheel_joint</right_joint>
      <child_frame_id>robot/base_link</child_frame_id>
      <wheel_separation>0.291</wheel_separation>
      <wheel_radius>0.25</wheel_radius>
      <odom_publish_frequency>10</odom_publish_frequency>
    </plugin>
    
    <plugin filename="gz-sim-sensors-system"
                    name="gz::sim::systems::Sensors">
                <render_engine>ogre2</render_engine>
    </plugin>

  </gazebo>
</robot>
